2025-04-27 01:11:59,331 INFO    StreamThr :1069857 [internal.py:wandb_internal():90] W&B internal server running at pid: 1069857, started at: 2025-04-27 01:11:59.329875
2025-04-27 01:11:59,332 DEBUG   HandlerThread:1069857 [handler.py:handle_request():141] handle_request: status
2025-04-27 01:11:59,333 INFO    HandlerThread:1069857 [handler.py:finish():810] shutting down handler
2025-04-27 01:12:00,334 ERROR   StreamThr :1069857 [internal.py:wandb_internal():165] Thread SenderThread:
Traceback (most recent call last):
  File "/gpfs/scratch/wz1492/miniconda3/envs/dino_wm/lib/python3.9/site-packages/wandb/sdk/internal/internal_util.py", line 51, in run
    self._run()
  File "/gpfs/scratch/wz1492/miniconda3/envs/dino_wm/lib/python3.9/site-packages/wandb/sdk/internal/internal_util.py", line 91, in _run
    self._setup()
  File "/gpfs/scratch/wz1492/miniconda3/envs/dino_wm/lib/python3.9/site-packages/wandb/sdk/internal/internal.py", line 302, in _setup
    self._sm = sender.SendManager(
  File "/gpfs/scratch/wz1492/miniconda3/envs/dino_wm/lib/python3.9/site-packages/wandb/sdk/internal/sender.py", line 226, in __init__
    self._api = internal_api.Api(
  File "/gpfs/scratch/wz1492/miniconda3/envs/dino_wm/lib/python3.9/site-packages/wandb/sdk/internal/internal_api.py", line 142, in __init__
    self._settings = Settings(
  File "/gpfs/scratch/wz1492/miniconda3/envs/dino_wm/lib/python3.9/site-packages/wandb/old/settings.py", line 25, in __init__
    self._global_settings.read([Settings._global_path()])
  File "/gpfs/scratch/wz1492/miniconda3/envs/dino_wm/lib/python3.9/site-packages/wandb/old/settings.py", line 112, in _global_path
    util.mkdir_exists_ok(config_dir)
  File "/gpfs/scratch/wz1492/miniconda3/envs/dino_wm/lib/python3.9/site-packages/wandb/util.py", line 861, in mkdir_exists_ok
    os.makedirs(path)
  File "/gpfs/scratch/wz1492/miniconda3/envs/dino_wm/lib/python3.9/os.py", line 225, in makedirs
    mkdir(name, mode)
PermissionError: [Errno 13] Permission denied: '/gpfs/home/wz1492/.config/wandb'
